Workbook

Sheet Axe en long
A1: Profil En Long Projet
A3: Nom du dessin | C3: Dessin5.dwg
A4: Nom de l'axe | C4: Nouveau Projet - Axe1_TEST
A5: Date du listing | C5: 03/12/2025 - 21:11:16
A6: Elts Caractéristiques | E6: Points de Contacts
A7: Nom | B7: Pente / Rayon | D7: Longueur | E7: Abscisse | F7: Altitude
A8: Pente 1 | B8: Pente | C8: 0.0074 | D8: 327.44 | E8: 0 | F8: 120.531
A9: Parabole 1 | B9: Rayon | C9: -50000.000 m | D9: 641.854 | E9: 327.44 | F9: 122.962 | G9: {=+[1]!D_PENTE(E8,F8,E9,F9)} -> 0.0074242609
B10: Sommet Absc. | C10: 698.706 m
B11: Sommet Alt. | C11: 124.341 m
A12: Pente 2 | B12: Pente | C12: -0.54 % | D12: 262.732 | E12: 969.294 | F12: 123.609
A13: Parabole 2 | B13: Rayon | C13: 75000.000 m | D13: 815.948 | E13: 1232.026 | F13: 122.187 | G13: {=+[1]!D_PENTE(E12,F12,E13,F13)} -> -0.0054123594
B14: Sommet Absc. | C14: 1637.908 m
B15: Sommet Alt. | C15: 121.088 m
A16: Pente 3 | B16: Pente | C16: 0.55 % | D16: 453.186 | E16: 2047.974 | F16: 122.209
A17: Parabole 3 | B17: Rayon | C17: -40000.000 m | D17: 516.5 | E17: 2501.16 | F17: 124.687 | G17: {=+[1]!D_PENTE(E16,F16,E17,F17)} -> 0.0054679536
B18: Sommet Absc. | C18: 2719.862 m
B19: Sommet Alt. | C19: 125.285 m
A20: Pente 4 | B20: Pente | C20: -0.74 % | D20: 141.257 | E20: 3017.661 | F20: 124.177
A21: Parabole 4 | B21: Rayon | C21: 70000.000 m | D21: 842.165 | E21: 3158.917 | F21: 123.125 | G21: {=+[1]!D_PENTE(E20,F20,E21,F21)} -> -0.0074474713
B22: Sommet Absc. | C22: 3680.064 m
B23: Sommet Alt. | C23: 121.185 m
A24: Pente 5 | B24: Pente | C24: 0.46 % | D24: 350.607 | E24: 4001.083 | F24: 121.921
A25: Parabole 5 | B25: Rayon | C25: -100000.000 m | D25: 1013.109 | E25: 4351.69 | F25: 123.529 | G25: {=+[1]!D_PENTE(E24,F24,E25,F25)} -> 0.0045863317
B26: Sommet Absc. | C26: 4810.288 m
B27: Sommet Alt. | C27: 124.581 m
A28: Pente 6 | B28: Pente | C28: -0.55 % | D28: 272.875 | E28: 5364.799 | F28: 123.043
E29: 5637.674 | F29: 121.53 | G29: {=+[1]!D_PENTE(E28,F28,E29,F29)} -> -0.0055446633
A30: Longueur totale de l'axe 5637.674 mètre(s)
A31: Longueur développée totale de l'axe 5637.728 mètre(s)
A35: PK (1) | B35: Z (2) | C35: Pente (3) | D35: Rayon (4)
A36: 0 | B36: 120.531 | C36: 0.007424 | D36: 0
A37: 327.44 | B37: 122.962 | C37: 0.007424 | D37: -50000
A38: 969.294 | B38: 123.609 | C38: -0.00541 | D38: 0
A39: 1232.026 | B39: 122.187 | C39: -0.00541 | D39: 75000
A40: 2047.974 | B40: 122.209 | C40: 0.005468 | D40: 0
A41: 2501.16 | B41: 124.687 | C41: 0.005468 | D41: -40000
A42: 3017.66 | B42: 124.177 | C42: -0.00745 | D42: 0
A43: 3158.917 | B43: 123.125 | C43: -0.00745 | D43: 70000
A44: 4001.082 | B44: 121.921 | C44: 0.004586 | D44: 0
...

Sheet Axe en plan
A1: Axe En Plan
A3: Nom du dessin | C3: Dessin5.dwg
A4: Nom de l'axe | C4: Nouveau Projet - Axe1_TEST
A5: Date du listing | C5: 03/12/2025 - 21:11:16
A6: Elts Caractéristiques | E6: Points de Contacts
A7: Nom | B7: Paramètres | D7: Longueur | E7: Abscisse | F7: X | G7: Y | H7: Gisement Tabulation | I7: Gisement Axe
A8: Droite 1 | B8: Gisement | C8: 254.4214g | D8: 801.736 | E8: 0 | F8: 6799.613 | G8: 1577.469 | H8: =INDEX(Tabulation!G:G, MATCH($E8, Tabulation!B:B, 0)) -> 354.4214 | I8: =+H8-100 -> 254.4214
A9: Arc 1 | B9: Rayon | C9: -1000 | D9: 667.344 | E9: 801.736 | F9: 6194.725 | G9: 1051.264 | H9: =INDEX(Tabulation!G:G, MATCH($E9, Tabulation!B:B, 0)) -> 354.4214 | I9: =+H9-100 -> 254.4214
B10: Centre X | C10: 5538.394 | H10: =INDEX(Tabulation!G:G, MATCH($E10, Tabulation!B:B, 0))
B11: Centre Y | C11: 1805.736 | H11: =INDEX(Tabulation!G:G, MATCH($E11, Tabulation!B:B, 0))
A12: Clothoïde 1 | B12: Paramètre | C12: 750 | D12: 562.5 | E12: 1469.08 | F12: 5586.976 | G12: 806.917 | H12: =INDEX(Tabulation!G:G, MATCH($E12, Tabulation!B:B, 0)) -> 396.9059 | I12: =+H12-100 -> 296.9059
A13: Droite 2 | B13: Gisement | C13: 314.8108g | D13: 818.395 | E13: 2031.58 | F13: 5031.855 | G13: 884.558 | H13: =INDEX(Tabulation!G:G, MATCH($E13, Tabulation!B:B, 0)) -> 14.8108 | I13: =+H13-100+400 -> 314.8108
A14: Clothoïde 2 | B14: Paramètre | C14: 750 | D14: 375 | E14: 2849.975 | F14: 4235.508 | G14: 1073.243 | H14: =INDEX(Tabulation!G:G, MATCH($E14, Tabulation!B:B, 0)) -> 14.8108 | I14: =+H14-100+400 -> 314.8108
A15: Arc 2 | B15: Rayon | C15: 1500 | D15: 602.015 | E15: 3224.975 | F15: 3867.582 | G15: 1144.379 | H15: =INDEX(Tabulation!G:G, MATCH($E15, Tabulation!B:B, 0)) -> 6.8531 | I15: =+H15-100+400 -> 306.8531
B16: Centre X | C16: 3706.422 | H16: =INDEX(Tabulation!G:G, MATCH($E16, Tabulation!B:B, 0))
B17: Centre Y | C17: -346.938 | H17: =INDEX(Tabulation!G:G, MATCH($E17, Tabulation!B:B, 0))
A18: Clothoïde 3 | B18: Paramètre | C18: -865.597 | D18: 499.505 | E18: 3826.99 | F18: 3272.185 | G18: 1088.833 | H18: =INDEX(Tabulation!G:G, MATCH($E18, Tabulation!B:B, 0)) -> 381.3028 | I18: =+H18-100 -> 281.3028
A19: Clothoïde 4 | B19: Paramètre | C19: -865.597 | D19: 624.382 | E19: 4326.495 | F19: 2813.597 | G19: 892.394 | H19: =INDEX(Tabulation!G:G, MATCH($E19, Tabulation!B:B, 0)) -> 370.703 | I19: =+H19-100 -> 270.703
A20: Arc 3 | B20: Rayon | C20: -1200 | D20: 162.421 | E20: 4950.877 | F20: 2234.016 | G20: 665.241 | H20: =INDEX(Tabulation!G:G, MATCH($E20, Tabulation!B:B, 0)) -> 387.2652 | I20: =+H20-100 -> 287.2652
B21: Centre X | C21: 1995.568 | H21: =INDEX(Tabulation!G:G, MATCH($E21, Tabulation!B:B, 0))
B22: Centre Y | C22: 1841.312 | H22: =INDEX(Tabulation!G:G, MATCH($E22, Tabulation!B:B, 0))
A23: Droite 3 | B23: Gisement | C23: 295.8819g | D23: 524.376 | E23: 5113.298 | F23: 2073.138 | G23: 643.821 | H23: =INDEX(Tabulation!G:G, MATCH($E23, Tabulation!B:B, 0)) -> 395.8819 | I23: =+H23-100 -> 295.8819
E24: 5637.674 | F24: 1549.859 | G24: 609.925 | H24: =INDEX(Tabulation!G:G, MATCH($E24, Tabulation!B:B, 0)) -> 395.8819 | I24: =+H24-100 -> 295.8819
A25: Longueur totale de l'axe 5637.674 mètre(s)
A28: PK (1) | B28: X (2) | C28: Y (3) | D28: Gisement (4) | E28: Rayon (5) | F28: ParamA (6) | G28: X_Fin/IP (7) | H28: Y_Fin/IP (8) | I28: A1 (9) | J28: R1 (10) | K28: A2 (11) | L28: R2 (12) | M28: Type (13)
A29: 0 | B29: 6799.613 | C29: 1577.469 | D29: 254.4214 | E29: 0 | F29: 0 | G29: 0 | H29: 0 | I29: 0 | J29: 0 | K29: 0 | L29: 0 | M29: ligne
A30: 801.736 | B30: 6194.725 | C30: 1051.264 | D30: 254.4214 | E30: -1000 | F30: 0 | G30: 0 | H30: 0 | I30: 0 | J30: 0 | K30: 0 | L30: 0 | M30: arc
A31: 1469.08 | B31: 5586.976 | C31: 806.917 | D31: 396.9059 | E31: -1000 | F31: 750 | G31: 5031.855 | H31: 884.558 | I31: 750 | J31: -1000 | K31: 0 | L31: 0 | M31: clothoInverse
A32: 2031.58 | B32: 5031.855 | C32: 884.558 | D32: 314.8108 | E32: 0 | F32: 0 | G32: 0 | H32: 0 | I32: 0 | J32: 0 | K32: 0 | L32: 0 | M32: ligne
A33: 2849.975 | B33: 4235.508 | C33: 1073.243 | D33: 314.8108 | E33: 1500 | F33: 750 | G33: 0 | H33: 0 | I33: 0 | J33: 0 | K33: 0 | L33: 0 | M33: clotho
A34: 3224.975 | B34: 3867.582 | C34: 1144.379 | D34: 306.8531 | E34: 1500 | F34: 0 | G34: 0 | H34: 0 | I34: 0 | J34: 0 | K34: 0 | L34: 0 | M34: arc
A35: 3826.99 | B35: 3272.185 | C35: 1088.833 | D35: 81.3028 | E35: 0 | F35: 0 | G35: 2813.597 | H35: 892.394 | I35: -865.597 | J35: 1500 | K35: -865.597 | L35: -1200 | M35: liaisonS
A36: 4950.877 | B36: 2234.016 | C36: 665.241 | D36: 287.2652 | E36: -1200 | F36: 0 | G36: 0 | H36: 0 | I36: 0 | J36: 0 | K36: 0 | L36: 0 | M36: arc
A37: 5113.2985 | B37: 2073.138 | C37: 643.821 | D37: 295.8819 | E37: 0 | F37: 0 | G37: 0 | H37: 0 | I37: 0 | J37: 0 | K37: 0 | L37: 0 | M37: ligne
A38: 999999999 | B38: 0 | C38: 0 | D38: 0 | E38: 0 | F38: 0 | G38: 0 | H38: 0 | I38: 0 | J38: 0 | K38: 0 | L38: 0 | M38: FIN

Sheet Entrée terre
A1: Edition des entrées en terre
A3: Nom du dessin | C3: Dessin5.dwg
A4: Nom de l'axe | C4: Nouveau Projet - Axe1_TEST
A5: Date du listing | C5: 03/12/2025 - 21:11:16
A6: Num. | B6: Abscisse | D6: Côté | E6: Gauche | H6: Côté | I6: Droit
C7: Assiette | D7: X | E7: Y | F7: Cote | G7: Assiette | H7: X | I7: Y | J7: Cote
A8: P01 | B8: 0 | C8: -6.695 | D8: 6804.007 | E8: 1572.417 | F8: 123.176 | G8: 6.687 | H8: 6795.224 | I8: 1582.514 | J8: 123.168
A9: P02 | B9: 20 | C9: -6.532 | D9: 6788.811 | E9: 1559.413 | F9: 123.162 | G9: 6.525 | H9: 6780.241 | I9: 1569.265 | J9: 123.154
A10: P03 | B10: 40 | C10: -6.369 | D10: 6773.615 | E10: 1546.41 | F10: 123.147 | G10: 6.362 | H10: 6765.258 | I10: 1556.015 | J10: 123.14
A11: P04 | B11: 60 | C11: -6.207 | D11: 6758.418 | E11: 1533.406 | F11: 123.133 | G11: 6.2 | H11: 6750.276 | I11: 1542.766 | J11: 123.126
A12: P05 | B12: 80 | C12: -6.044 | D12: 6743.222 | E12: 1520.402 | F12: 123.119 | G12: 6.037 | H12: 6735.293 | I12: 1529.517 | J12: 123.112
A13: P06 | B13: 100 | C13: -5.881 | D13: 6728.026 | E13: 1507.398 | F13: 123.105 | G13: 5.874 | H13: 6720.31 | I13: 1516.267 | J13: 123.098
A14: P07 | B14: 120 | C14: -5.718 | D14: 6712.829 | E14: 1494.394 | F14: 123.09 | G14: 5.712 | H14: 6705.327 | I14: 1503.018 | J14: 123.084
A15: P08 | B15: 140 | C15: -5.556 | D15: 6697.633 | E15: 1481.391 | F15: 123.076 | G15: 5.549 | H15: 6690.345 | I15: 1489.769 | J15: 123.07
A16: P09 | B16: 160 | C16: -5.393 | D16: 6682.437 | E16: 1468.387 | F16: 123.062 | G16: 5.387 | H16: 6675.362 | I16: 1476.519 | J16: 123.056
A17: P10 | B17: 180 | C17: -5.23 | D17: 6667.24 | E17: 1455.383 | F17: 123.047 | G17: 5.224 | H17: 6660.379 | I17: 1463.27 | J17: 123.041
A18: P11 | B18: 200 | C18: -5.067 | D18: 6652.044 | E18: 1442.379 | F18: 123.033 | G18: 5.061 | H18: 6645.397 | I18: 1450.021 | J18: 123.027
A19: P12 | B19: 220 | C19: -4.904 | D19: 6636.848 | E19: 1429.375 | F19: 123.019 | G19: 4.899 | H19: 6630.414 | I19: 1436.772 | J19: 123.013
... A299: P292 | B299: 5637.674 | C299: -5.075 | D299: 1550.187 | E299: 604.86 | F299: 122.555 | G299: 5.065 | H299: 1549.532 | I299: 614.979 | J299: 122.545

Sheet Tabulation
A1: Profils En Travers
A3: Nom du dessin | C3: Dessin5.dwg
A4: Nom de l'axe | C4: Nouveau Projet - Axe1_TEST
A5: Date du listing | C5: 03/12/2025 - 21:11:16
A6: Convention de signe des dévers :
A8: Num. | B8: Abscisse | C8: Axe Plan | D8: Axe Long | E8: Z TN | F8: Z Projet | G8: isement | H8: X | I8: Y | J8: Dévers | L8: Pente
J9: Gauche | K9: Droite | L9: long.
A10: P01 | B10: 0 | C10: Droite 1 | D10: Pente 1 | E10: 123.172 | F10: 120.531 | G10: 354.4214 | H10: 6799.613 | I10: 1577.469 | L10: 0.74 | N10: {=[1]!ClothoidS_Gt(#REF!,#REF!,#REF!,#REF!,#REF!,#REF!,#REF!,#REF!,#REF!,B10)} -> #VALUE!
A11: P02 | B11: 20 | C11: Droite 1 | D11: Pente 1 | E11: 123.158 | F11: 120.679 | G11: 354.4214 | H11: 6784.523 | I11: 1564.342 | L11: 0.74
A12: P03 | B12: 40 | C12: Droite 1 | D12: Pente 1 | E12: 123.144 | F12: 120.828 | G12: 354.4214 | H12: 6769.434 | I12: 1551.215 | L12: 0.74
A13: P04 | B13: 60 | C13: Droite 1 | D13: Pente 1 | E13: 123.13 | F13: 120.977 | G13: 354.4214 | H13: 6754.345 | I13: 1538.089 | L13: 0.74
A14: P05 | B14: 80 | C14: Droite 1 | D14: Pente 1 | E14: 123.115 | F14: 121.125 | G14: 354.4214 | H14: 6739.255 | I14: 1524.962 | L14: 0.74
A15: P06 | B15: 100 | C15: Droite 1 | D15: Pente 1 | E15: 123.101 | F15: 121.274 | G15: 354.4214 | H15: 6724.166 | I15: 1511.835 | L15: 0.74
A16: P07 | B16: 120 | C16: Droite 1 | D16: Pente 1 | E16: 123.087 | F16: 121.422 | G16: 354.4214 | H16: 6709.076 | I16: 1498.709 | L16: 0.74
A17: P08 | B17: 140 | C17: Droite 1 | D17: Pente 1 | E17: 123.073 | F17: 121.571 | G17: 354.4214 | H17: 6693.987 | I17: 1485.582 | L17: 0.74
A18: P09 | B18: 160 | C18: Droite 1 | D18: Pente 1 | E18: 123.059 | F18: 121.719 | G18: 354.4214 | H18: 6678.897 | I18: 1472.455 | L18: 0.74
A19: P10 | B19: 180 | C19: Droite 1 | D19: Pente 1 | E19: 123.044 | F19: 121.868 | G19: 354.4214 | H19: 6663.808 | I19: 1459.329 | L19: 0.74
A20: P11 | B20: 200 | C20: Droite 1 | D20: Pente 1 | E20: 123.03 | F20: 122.016 | G20: 354.4214 | H20: 6648.718 | I20: 1446.202 | L20: 0.74
A21: P12 | B21: 220 | C21: Droite 1 | D21: Pente 1 | E21: 123.016 | F21: 122.165 | G21: 354.4214 | H21: 6633.629 | I21: 1433.076 | L21: 0.74
A22: P13 | B22: 240 | C22: Droite 1 | D22: Pente 1 | E22: 123.002 | F22: 122.313 | G22: 354.4214 | H22: 6618.54 | I22: 1419.949 | L22: 0.74
... A207: P198 | B207: 3826.99 | C207: Arc 2 | D207: Parabole 4 | E207: 123.348 | F207: 121.339 | G207: 381.3028 | H207: 3272.185 | I207: 1088.833 | L207: 0.21
A208: P199 | B208: 3840 | C208: Clothoïde 3 | D208: Parabole 4 | E208: 123.343 | F208: 121.368 | G208: 380.7578 | H208: 3259.748 | I208: 1085.013 | L208: 0.23 | N208: {=[1]!ClothoidS_Gt(#REF!,#REF!,#REF!,#REF!,#REF!,#REF!,#REF!,#REF!,#REF!,B208)} -> #VALUE! | O208: =+N208-G208+100 -> #VALUE!
A209: P200 | B209: 3860 | C209: Clothoïde 3 | D209: Parabole 4 | E209: 123.336 | F209: 121.416 | G209: 379.9481 | H209: 3240.694 | I209: 1078.937 | L209: 0.26 | N209: {=[1]!ClothoidS_Gt(#REF!,#REF!,#REF!,#REF!,#REF!,#REF!,#REF!,#REF!,#REF!,B209)} -> #VALUE! | O209: =+N209-G209+100 -> #VALUE!
A210: P201 | B210: 3880 | C210: Clothoïde 3 | D210: Parabole 4 | E210: 123.329 | F210: 121.471 | G210: 379.1723 | H210: 3221.716 | I210: 1072.625 | L210: 0.29 | N210: {=[1]!ClothoidS_Gt(#REF!,#REF!,#REF!,#REF!,#REF!,#REF!,#REF!,#REF!,#REF!,B210)} -> #VALUE! | O210: =+N210-G210+100 -> #VALUE!
A211: P202 | B211: 3900 | C211: Clothoïde 3 | D211: Parabole 4 | E211: 123.322 | F211: 121.531 | G211: 378.4306 | H211: 3202.815 | I211: 1066.087 | L211: 0.31 | N211: {=[1]!ClothoidS_Gt(#REF!,#REF!,#REF!,#REF!,#REF!,#REF!,#REF!,#REF!,#REF!,B211)} -> #VALUE! | O211: =+N211-G211+100 -> #VALUE!
A212: P203 | B212: 3920 | C212: Clothoïde 3 | D212: Parabole 4 | E212: 123.316 | F212: 121.596 | G212: 377.7228 | H212: 3183.99 | I212: 1059.334 | L212: 0.34 | N212: {=[1]!ClothoidS_Gt(#REF!,#REF!,#REF!,#REF!,#REF!,#REF!,#REF!,#REF!,#REF!,B212)} -> #VALUE! | O212: =+N212-G212+100 -> #VALUE!
A213: P204 | B213: 3940 | C213: Clothoïde 3 | D213: Parabole 4 | E213: 123.309 | F213: 121.668 | G213: 377.0491 | H213: 3165.239 | I213: 1052.377 | L213: 0.37 | N213: {=[1]!ClothoidS_Gt(#REF!,#REF!,#REF!,#REF!,#REF!,#REF!,#REF!,#REF!,#REF!,B213)} -> #VALUE! | O213: =+N213-G213+100 -> #VALUE!
A214: P205 | B214: 3960 | C214: Clothoïde 3 | D214: Parabole 4 | E214: 123.303 | F214: 121.745 | G214: 376.4093 | H214: 3146.56 | I214: 1045.227 | L214: 0.4 | N214: {=[1]!ClothoidS_Gt(#REF!,#REF!,#REF!,#REF!,#REF!,#REF!,#REF!,#REF!,#REF!,B214)} -> #VALUE! | O214: =+N214-G214+100 -> #VALUE!
A215: P206 | B215: 3980 | C215: Clothoïde 3 | D215: Parabole 4 | E215: 123.297 | F215: 121.828 | G215: 375.8035 | H215: 3127.953 | I215: 1037.895 | L215: 0.43 | N215: {=[1]!ClothoidS_Gt(#REF!,#REF!,#REF!,#REF!,#REF!,#REF!,#REF!,#REF!,#REF!,B215)} -> #VALUE! | O215: =+N215-G215+100 -> #VALUE!
A216: P207 | B216: 4000 | C216: Clothoïde 3 | D216: Parabole 4 | E216: 123.291 | F216: 121.916 | G216: 375.2316 | H216: 3109.414 | I216: 1030.391 | L216: 0.46 | N216: {=[1]!ClothoidS_Gt(#REF!,#REF!,#REF!,#REF!,#REF!,#REF!,#REF!,#REF!,#REF!,B216)} -> #VALUE! | O216: =+N216-G216+100 -> #VALUE!
A217: P208 | B217: 4020 | C217: Clothoïde 3 | D217: Pente 5 | E217: 123.285 | F217: 122.008 | G217: 374.6938 | H217: 3090.941 | I217: 1022.726 | L217: 0.46 | N217: {=[1]!ClothoidS_Gt(#REF!,#REF!,#REF!,#REF!,#REF!,#REF!,#REF!,#REF!,#REF!,B217)} -> #VALUE! | O217: =+N217-G217+100 -> #VALUE!
A218: P209 | B218: 4040 | C218: Clothoïde 3 | D218: Pente 5 | E218: 123.279 | F218: 122.1 | G218: 374.19 | H218: 3072.532 | I218: 1014.91 | L218: 0.46 | N218: {=[1]!ClothoidS_Gt(#REF!,#REF!,#REF!,#REF!,#REF!,#REF!,#REF!,#REF!,#REF!,B218)} -> #VALUE! | O218: =+N218-G218+100 -> #VALUE!
A219: P210 | B219: 4060 | C219: Clothoïde 3 | D219: Pente 5 | E219: 123.273 | F219: 122.191 | G219: 373.7201 | H219: 3054.183 | I219: 1006.953 | L219: 0.46 | N219: {=[1]!ClothoidS_Gt(#REF!,#REF!,#REF!,#REF!,#REF!,#REF!,#REF!,#REF!,#REF!,B219)} -> #VALUE! | O219: =+N219-G219+100 -> #VALUE!
... A264: P255 | B264: 4940 | C264: Clothoïde 4 | D264: Parabole 5 | E264: 122.912 | F264: 124.496 | G264: 386.6932 | H264: 2244.665 | I264: 667.45 | L264: -0.13 | N264: {=[1]!ClothoidS_Gt(#REF!,#REF!,#REF!,#REF!,#REF!,#REF!,#REF!,#REF!,#REF!,B264)} -> #VALUE! | O264: =+N264-G264+100 -> #VALUE!
A265: P256 | B265: 4950.877 | C265: Arc 3 | D265: Parabole 5 | E265: 122.906 | F265: 124.482 | G265: 387.2652 | H265: 2234.016 | I265: 665.241 | L265: -0.14
A266: P257 | B266: 4960 | C266: Arc 3 | D266: Parabole 5 | E266: 122.901 | F266: 124.468 | G266: 387.7492 | H266: 2225.067 | I266: 663.462 | L266: -0.15
A267: P258 | B267: 4980 | C267: Arc 3 | D267: Parabole 5 | E267: 122.893 | F267: 124.437 | G267: 388.8102 | H267: 2205.406 | I267: 659.801 | L267: -0.17
A268: P259 | B268: 5000 | C268: Arc 3 | D268: Parabole 5 | E268: 122.884 | F268: 124.401 | G268: 389.8713 | H268: 2185.685 | I268: 656.468 | L268: -0.19
A269: P260 | B269: 5020 | C269: Arc 3 | D269: Parabole 5 | E269: 122.875 | F269: 124.361 | G269: 390.9323 | H269: 2165.913 | I269: 653.464 | L269: -0.21
A270: P261 | B270: 5040 | C270: Arc 3 | D270: Parabole 5 | E270: 122.866 | F270: 124.317 | G270: 391.9933 | H270: 2146.092 | I270: 650.79 | L270: -0.23
...
